<?xml version="1.0" ?>
<!-- =================================================================================== -->
<!-- |    This document was autogenerated by xacro from thymio_simple.urdf.xacro       | -->
<!-- |    EDITING THIS FILE BY HAND IS NOT RECOMMENDED                                 | -->
<!-- =================================================================================== -->
<robot name="thymio">
  <material name="white">
    <color rgba="1 1 1 1"/>
  </material>
  <material name="black">
    <color rgba="0 0 0 1"/>
  </material>
  <material name="blue">
    <color rgba="0 0 0.8 1"/>
  </material>
  <material name="yellow">
    <color rgba="1 1 0 1"/>
  </material>
  <material name="green">
    <color rgba="0 1 0 1"/>
  </material>
  <material name="brown">
    <color rgba="0.6 0.4 0.2 1.0"/>
  </material>
  <!-- Colours -->
  <gazebo reference="sensor_left">
    <material>Gazebo/Black</material>
  </gazebo>
  <gazebo reference="sensor_right">
    <material>Gazebo/Black</material>
  </gazebo>
  <gazebo reference="sensor_right">
    <material>Gazebo/Black</material>
  </gazebo>
  <gazebo reference="right_wheel_link">
    <material>Gazebo/Black</material>
  </gazebo>
  <gazebo reference="left_wheel_link">
    <material>Gazebo/Black</material>
  </gazebo>
  <gazebo reference="base_link">
    <material>Gazebo/White</material>
  </gazebo>
  <!-- Diff drive -->
  <gazebo>
    <plugin filename="libgazebo_ros_diff_drive.so" name="differential_drive_controller">
      <alwaysOn>true</alwaysOn>
      <updateRate>10</updateRate>
      <torque>100</torque>
      <leftJoint>left_wheel_joint</leftJoint>
      <rightJoint>right_wheel_joint</rightJoint>
      <wheelSeparation>0.0955</wheelSeparation>
      <wheelDiameter>0.044</wheelDiameter>
      <commandTopic>cmd_vel</commandTopic>
      <odometryTopic>odom</odometryTopic>
      <odometryFrame>odom</odometryFrame>
      <robotBaseFrame>base_link</robotBaseFrame>
    </plugin>
  </gazebo>
  <link name="base_link">
    <visual>
      <origin rpy="0 0 0" xyz="0 0 0"/>
      <geometry>
        <box size="0.11 0.112 0.045"/>
      </geometry>
      <material name="white"/>
    </visual>
    <collision>
      <origin rpy="0 0 0" xyz="0 0 0"/>
      <geometry>
        <box size="0.11 0.112 0.045"/>
      </geometry>
      <material name="white"/>
    </collision>
    <!-- Implement the caster wheel -->
    <visual>
      <origin rpy="0 0 0" xyz="0.03 0 -0.0225"/>
      <geometry>
        <sphere radius="0.0095"/>
      </geometry>
      <material name="white"/>
    </visual>
    <collision>
      <origin rpy="0 0 0" xyz="0.03 0 -0.0225"/>
      <geometry>
        <sphere radius="0.0095"/>
      </geometry>
      <material name="white"/>
    </collision>
    <inertial>
      <mass value="0.21600000000000003"/>
      <inertia ixx="0.00026224200000000004" ixy="0" ixz="0" iyy="0.00025425" iyz="0" izz="0.00025425"/>
    </inertial>
  </link>
  <!-- Implement the left wheel -->
  <link name="left_wheel">
    <visual>
      <origin rpy="0 0 0" xyz="0 0 0"/>
      <geometry>
        <cylinder length="0.015" radius="0.022"/>
      </geometry>
      <material name="black"/>
    </visual>
    <collision>
      <origin rpy="0 0 0" xyz="0 0 0"/>
      <geometry>
        <cylinder length="0.015" radius="0.022"/>
      </geometry>
      <material name="black"/>
    </collision>
    <inertial>
      <mass value="0.027000000000000003"/>
      <inertia ixx="3.7732500000000003e-06" ixy="0" ixz="0" iyy="3.7732500000000003e-06" iyz="0" izz="6.534e-06"/>
    </inertial>
  </link>
  <!-- Implement the right wheel -->
  <link name="right_wheel">
    <visual>
      <origin rpy="0 0 0" xyz="0 0 0"/>
      <geometry>
        <cylinder length="0.015" radius="0.022"/>
      </geometry>
      <material name="black"/>
    </visual>
    <collision>
      <origin rpy="0 0 0" xyz="0 0 0"/>
      <geometry>
        <cylinder length="0.015" radius="0.022"/>
      </geometry>
      <material name="black"/>
    </collision>
    <inertial>
      <mass value="0.027000000000000003"/>
      <inertia ixx="3.7732500000000003e-06" ixy="0" ixz="0" iyy="3.7732500000000003e-06" iyz="0" izz="6.534e-06"/>
    </inertial>
  </link>
  <!-- Implement the joint for the left wheel -->
  <joint name="left_wheel_joint" type="continuous">
    <parent link="base_link"/>
    <child link="left_wheel"/>
    <axis rpy="0 0 0" xyz="0 1 0"/>
    <origin rpy="1.57079632679 0 0" xyz="-0.03 0.056 -0.0100"/>
  </joint>
  <!-- Implement the joint for the right wheel -->
  <joint name="right_wheel_joint" type="continuous">
    <parent link="base_link"/>
    <child link="right_wheel"/>
    <axis rpy="0 0 0" xyz="0 1 0"/>
    <origin rpy="1.57079632679 0 0" xyz="-0.03 -0.056 -0.0100"/>
  </joint>
  <!-- Add your sensors using the macro -->
</robot>

